<?xml version='1.0'?>

<robot name="Rover" xmlns:xacro="http://www.ros.org/wiki/xacro">

  <gazebo>
        <plugin name="gazebo_ros_control" filename="libgazebo_ros_control.so">
        </plugin>
</gazebo>



<link name="base_link">

        <inertial>
	<origin xyz="0 0 0" rpy="0 0 0"/>
            <mass value="19.0"/>
            <inertia ixx=" 0.206625" iyy="0.691125" izz=" 0.8949" ixy="0" ixz="0" iyz="0"/>
        </inertial>

        <collision>
	<origin xyz="0 0 0" rpy="0 0 0"/>
            <geometry>
	
                <box size="0.66 0.36 0.03"/>
            </geometry>

        </collision>

        <visual>
	<origin xyz="0 0 0" rpy="0 0 0"/>
            <geometry>
                <box size="0.66 0.36 0.03"/>
            </geometry>

            <material name="silver">
                <color rgba="0 1 0 1"/>
            </material>
        </visual>

</link>

<gazebo reference="base_link">
        <material>Gazebo/Green</material>
	<kp>1000000.0</kp>
        <kd>1000000.0</kd>
        <mu1>0.1</mu1>
        <mu2>0.1</mu2>
</gazebo>



<link name="leg1">

      <inertial>
	<origin xyz="0.01 0 0" rpy="0 0 0"/>
        <mass value="2.4"/>
        <inertia ixx="0.08036" iyy="0.07946" izz=" 0.00106" ixy="0" ixz="0" iyz="0"/>
      </inertial>

      <collision>
	<origin xyz="0.01 0 0" rpy="0 0 0"/>
        <geometry>
            <box size="0.02 0.07 0.63"/>
        </geometry>

      </collision>

      <visual>
	  <origin xyz="0.01 0 0" rpy="0 0 0"/>
          <geometry>
              <box size="0.02 0.07 0.63"/>
          </geometry>

          <material name="silver">
              <color rgba="1 0.5 0.75 1"/>
          </material>
      </visual>

</link>

<gazebo reference="leg1">
        <material>Gazebo/Red</material>
	<kp>1000000.0</kp>
        <kd>1000000.0</kd>
        <mu1>0.1</mu1>
        <mu2>0.1</mu2>
</gazebo>

<joint name="Base_Link_Leg_1" type="prismatic">
    	<parent link="base_link"/>
    	<child link="leg1"/>
        <origin xyz="0.33 0.145 0" rpy="0 0 0"/>
        <limit lower="-0.35" upper="0.35" effort="10.0" velocity="1.0"/>
        <axis xyz="0 0 1"/>
</joint>




<link name="wheel1">
    
        <inertial>
	<origin xyz="0 0 0.012" rpy="0 0 0"/> 
            <mass value="0.21"/>
            <inertia ixx="6.2708e-5" iyy="6.2708e-5" izz="0.000125" ixy="0" ixz="0" iyz="0"/>
        </inertial>
        <collision>
	<origin xyz="0 0 0.012" rpy="0 0 0"/>
            <geometry>
                <cylinder length="0.024" radius="0.032"/>
            </geometry>
        </collision>

        <visual>
	<origin xyz="0 0 0.012" rpy="0 0 0"/>
            <geometry>
                <cylinder length="0.024" radius="0.032"/>
            </geometry>
            <material name="black">
                <color rgba="0 0 0 1"/>
            </material>
        </visual>
</link>

<gazebo reference="wheel1">
        <material>Gazebo/Green</material>
	<kp>1000000.0</kp>
        <kd>1000000.0</kd>
        <mu1>100.0</mu1>
        <mu2>100.0</mu2>
</gazebo>

<joint name="leg1_wheel1" type="continuous">
    	<parent link="leg1"/>
    	<child link="wheel1"/>
    	<origin xyz="0.02 0 -0.315" rpy="0 1.5708 0"/>
        <limit effort="10.0" velocity="10.0"/>
        <axis xyz="0 0 1"/>
</joint>



<!-- part 22222222222222222 -->

<link name="leg2">

      <inertial>
	<origin xyz="-0.01 0 0" rpy="0 0 0"/>
        <mass value="2.4"/>
        <inertia ixx="0.08036" iyy="0.07946" izz=" 0.00106" ixy="0" ixz="0" iyz="0"/>
      </inertial>

      <collision>
	<origin xyz="-0.01 0 0" rpy="0 0 0"/>
        <geometry>
            <box size="0.02 0.07 0.63"/>
        </geometry>

      </collision>

      <visual>
	  <origin xyz="-0.01 0 0" rpy="0 0 0"/>
          <geometry>
              <box size="0.02 0.07 0.63"/>
          </geometry>

          <material name="silver">
              <color rgba="1 0.5 0.75 1"/>
          </material>
      </visual>

</link>

<gazebo reference="leg2">
        <material>Gazebo/Red</material>
	<kp>1000000.0</kp>
        <kd>1000000.0</kd>
        <mu1>0.1</mu1>
        <mu2>0.1</mu2>
</gazebo>

<joint name="Base_Link_Leg_2" type="prismatic">
    	<parent link="base_link"/>
    	<child link="leg2"/>
        <origin xyz="-0.33 0.145 0" rpy="0 0 0"/>
        <limit lower="-0.35" upper="0.35" effort="10.0" velocity="1.0"/>
        <axis xyz="0 0 1"/>
</joint>



<link name="wheel2">
    
        <inertial>
	<origin xyz="0 0 -0.012" rpy="0 0 0"/> 
            <mass value="0.21"/>
            <inertia ixx="6.2708e-5" iyy="6.2708e-5" izz="0.000125" ixy="0" ixz="0" iyz="0"/>
        </inertial>
        <collision>
	<origin xyz="0 0 -0.012" rpy="0 0 0"/>
            <geometry>
                <cylinder length="0.024" radius="0.032"/>
            </geometry>
        </collision>

        <visual>
	<origin xyz="0 0 -0.012" rpy="0 0 0"/>
            <geometry>
                <cylinder length="0.024" radius="0.032"/>
            </geometry>
            <material name="black">
                <color rgba="0 0 0 1"/>
            </material>
        </visual>
</link>

<gazebo reference="wheel2">
        <material>Gazebo/Green</material>
	<kp>1000000.0</kp>
        <kd>1000000.0</kd>
        <mu1>0.1</mu1>
        <mu2>0.1</mu2>
</gazebo>

<joint name="leg2_wheel2" type="continuous">
    	<parent link="leg2"/>
    	<child link="wheel2"/>
    	<origin xyz="-0.02 0 -0.315" rpy="0 1.5708 0"/>
        <limit effort="10.0" velocity="10.0"/>
        <axis xyz="0 0 1"/>
</joint>



<!-- part 333333333333333 -->
<link name="leg3">

      <inertial>
	<origin xyz="0.01 0 0" rpy="0 0 0"/>
        <mass value="2.4"/>
        <inertia ixx="0.08036" iyy="0.07946" izz=" 0.00106" ixy="0" ixz="0" iyz="0"/>
      </inertial>

      <collision>
	<origin xyz="0.01 0 0" rpy="0 0 0"/>
        <geometry>
            <box size="0.02 0.07 0.63"/>
        </geometry>

      </collision>

      <visual>
	  <origin xyz="0.01 0 0" rpy="0 0 0"/>
          <geometry>
              <box size="0.02 0.07 0.63"/>
          </geometry>

          <material name="silver">
              <color rgba="1 0.5 0.75 1"/>
          </material>
      </visual>

</link>

<gazebo reference="leg3">
        <material>Gazebo/Red</material>
	<kp>1000000.0</kp>
        <kd>1000000.0</kd>
        <mu1>0.1</mu1>
        <mu2>0.1</mu2>
</gazebo>

<joint name="Base_Link_Leg_3" type="prismatic">
    	<parent link="base_link"/>
    	<child link="leg3"/>
        <origin xyz="0.33 0 0" rpy="0 0 0"/>
        <limit lower="-0.35" upper="0.35" effort="10.0" velocity="1.0"/>
        <axis xyz="0 0 1"/>
</joint>

<link name="wheel3">
    
        <inertial>
	<origin xyz="0 0 0.012" rpy="0 0 0"/> 
            <mass value="0.21"/>
            <inertia ixx="6.2708e-5" iyy="6.2708e-5" izz="0.000125" ixy="0" ixz="0" iyz="0"/>
        </inertial>
        <collision>
	<origin xyz="0 0 0.012" rpy="0 0 0"/>
            <geometry>
                <cylinder length="0.024" radius="0.032"/>
            </geometry>
        </collision>

        <visual>
	<origin xyz="0 0 0.012" rpy="0 0 0"/>
            <geometry>
                <cylinder length="0.024" radius="0.032"/>
            </geometry>
            <material name="black">
                <color rgba="0 0 0 1"/>
            </material>
        </visual>
</link>

<gazebo reference="wheel3">
        <material>Gazebo/Green</material>
	<kp>1000000.0</kp>
        <kd>1000000.0</kd>
        <mu1>0.1</mu1>
        <mu2>0.1</mu2>
</gazebo>

<joint name="leg3_wheel3" type="continuous">
    	<parent link="leg3"/>
    	<child link="wheel3"/>
    	<origin xyz="0.02 0 -0.315" rpy="0 1.5708 0"/>
        <limit effort="10.0" velocity="10.0"/>
        <axis xyz="0 0 1"/>
</joint>
<!-- part 44444444444444444 -->
<link name="leg4">

      <inertial>
	<origin xyz="-0.01 0 0" rpy="0 0 0"/>
        <mass value="2.4"/>
        <inertia ixx="0.08036" iyy="0.07946" izz=" 0.00106" ixy="0" ixz="0" iyz="0"/>
      </inertial>

      <collision>
	<origin xyz="-0.01 0 0" rpy="0 0 0"/>
        <geometry>
            <box size="0.02 0.07 0.63"/>
        </geometry>

      </collision>

      <visual>
	  <origin xyz="-0.01 0 0" rpy="0 0 0"/>
          <geometry>
              <box size="0.02 0.07 0.63"/>
          </geometry>

          <material name="silver">
              <color rgba="1 0.5 0.75 1"/>
          </material>
      </visual>

</link>

<gazebo reference="leg4">
        <material>Gazebo/Red</material>
	<kp>1000000.0</kp>
        <kd>1000000.0</kd>
        <mu1>0.1</mu1>
        <mu2>0.1</mu2>
</gazebo>

<joint name="Base_Link_Leg_4" type="prismatic">
    	<parent link="base_link"/>
    	<child link="leg4"/>
        <origin xyz="-0.33 0 0" rpy="0 0 0"/>
        <limit lower="-0.35" upper="0.35" effort="10.0" velocity="1.0"/>
        <axis xyz="0 0 1"/>
</joint>



<link name="wheel4">
    
        <inertial>
	<origin xyz="0 0 -0.012" rpy="0 0 0"/> 
            <mass value="0.21"/>
            <inertia ixx="6.2708e-5" iyy="6.2708e-5" izz="0.000125" ixy="0" ixz="0" iyz="0"/>
        </inertial>
        <collision>
	<origin xyz="0 0 -0.012" rpy="0 0 0"/>
            <geometry>
                <cylinder length="0.024" radius="0.032"/>
            </geometry>
        </collision>

        <visual>
	<origin xyz="0 0 -0.012" rpy="0 0 0"/>
            <geometry>
                <cylinder length="0.024" radius="0.032"/>
            </geometry>
            <material name="black">
                <color rgba="0 0 0 1"/>
            </material>
        </visual>
</link>

<gazebo reference="wheel4">
        <material>Gazebo/Green</material>
	<kp>1000000.0</kp>
        <kd>1000000.0</kd>
        <mu1>0.1</mu1>
        <mu2>0.1</mu2>
</gazebo>

<joint name="leg4_wheel4" type="continuous">
    	<parent link="leg4"/>
    	<child link="wheel4"/>
    	<origin xyz="-0.02 0 -0.315" rpy="0 1.5708 0"/>
        <limit effort="10.0" velocity="10.0"/>
        <axis xyz="0 0 1"/>
</joint>

<!-- part 55555555 -->
<link name="leg5">

      <inertial>
	<origin xyz="0.01 0 0" rpy="0 0 0"/>
        <mass value="2.4"/>
        <inertia ixx="0.08036" iyy="0.07946" izz=" 0.00106" ixy="0" ixz="0" iyz="0"/>
      </inertial>

      <collision>
	<origin xyz="0.01 0 0" rpy="0 0 0"/>
        <geometry>
            <box size="0.02 0.07 0.63"/>
        </geometry>

      </collision>

      <visual>
	  <origin xyz="0.01 0 0" rpy="0 0 0"/>
          <geometry>
              <box size="0.02 0.07 0.63"/>
          </geometry>

          <material name="silver">
              <color rgba="1 0.5 0.75 1"/>
          </material>
      </visual>

</link>

<gazebo reference="leg5">
        <material>Gazebo/Red</material>
	<kp>1000000.0</kp>
        <kd>1000000.0</kd>
        <mu1>0.1</mu1>
        <mu2>0.1</mu2>
</gazebo>

<joint name="Base_Link_Leg_5" type="prismatic">
    	<parent link="base_link"/>
    	<child link="leg5"/>
        <origin xyz="0.33 -0.145 0" rpy="0 0 0"/>
        <limit lower="-0.35" upper="0.35" effort="10.0" velocity="1.0"/>
        <axis xyz="0 0 1"/>
</joint>



<link name="wheel5">
    
        <inertial>
	<origin xyz="0 0 0.012" rpy="0 0 0"/> 
            <mass value="0.21"/>
            <inertia ixx="6.2708e-5" iyy="6.2708e-5" izz="0.000125" ixy="0" ixz="0" iyz="0"/>
        </inertial>
        <collision>
	<origin xyz="0 0 0.012" rpy="0 0 0"/>
            <geometry>
                <cylinder length="0.024" radius="0.032"/>
            </geometry>
        </collision>

        <visual>
	<origin xyz="0 0 0.012" rpy="0 0 0"/>
            <geometry>
                <cylinder length="0.024" radius="0.032"/>
            </geometry>
            <material name="black">
                <color rgba="0 0 0 1"/>
            </material>
        </visual>
</link>

<gazebo reference="wheel5">
        <material>Gazebo/Green</material>
	<kp>1000000.0</kp>
        <kd>1000000.0</kd>
        <mu1>0.1</mu1>
        <mu2>0.1</mu2>
</gazebo>

<joint name="leg5_wheel5" type="continuous">
    	<parent link="leg5"/>
    	<child link="wheel5"/>
    	<origin xyz="0.02 0 -0.315" rpy="0 1.5708 0"/>
        <limit effort="10.0" velocity="10.0"/>
        <axis xyz="0 0 1"/>
</joint>


<!-- part 666666666666 -->
<link name="leg6">

      <inertial>
	<origin xyz="-0.01 0 0" rpy="0 0 0"/>
        <mass value="2.4"/>
        <inertia ixx="0.08036" iyy="0.07946" izz=" 0.00106" ixy="0" ixz="0" iyz="0"/>
      </inertial>

      <collision>
	<origin xyz="-0.01 0 0" rpy="0 0 0"/>
        <geometry>
            <box size="0.02 0.07 0.63"/>
        </geometry>

      </collision>

      <visual>
	  <origin xyz="-0.01 0 0" rpy="0 0 0"/>
          <geometry>
              <box size="0.02 0.07 0.63"/>
          </geometry>

          <material name="silver">
              <color rgba="1 0.5 0.75 1"/>
          </material>
      </visual>

</link>

<gazebo reference="leg6">
        <material>Gazebo/Red</material>
	<kp>1000000.0</kp>
        <kd>1000000.0</kd>
        <mu1>0.1</mu1>
        <mu2>0.1</mu2>
</gazebo>

<joint name="Base_Link_Leg_6" type="prismatic">
    	<parent link="base_link"/>
    	<child link="leg6"/>
        <origin xyz="-0.33 -0.145 0" rpy="0 0 0"/>
        <limit lower="-0.35" upper="0.35" effort="10.0" velocity="1.0"/>
        <axis xyz="0 0 1"/>
</joint>
<link name="wheel6">
    
        <inertial>
	<origin xyz="0 0 -0.012" rpy="0 0 0"/> 
            <mass value="0.21"/>
            <inertia ixx="6.2708e-5" iyy="6.2708e-5" izz="0.000125" ixy="0" ixz="0" iyz="0"/>
        </inertial>
        <collision>
	<origin xyz="0 0 -0.012" rpy="0 0 0"/>
            <geometry>
                <cylinder length="0.024" radius="0.032"/>
            </geometry>
        </collision>

        <visual>
	<origin xyz="0 0 -0.012" rpy="0 0 0"/>
            <geometry>
                <cylinder length="0.024" radius="0.032"/>
            </geometry>
            <material name="black">
                <color rgba="0 0 0 1"/>
            </material>
        </visual>
</link>

<gazebo reference="wheel6">
        <material>Gazebo/Green</material>
	<kp>1000000.0</kp>
        <kd>1000000.0</kd>
        <mu1>0.1</mu1>
        <mu2>0.1</mu2>
</gazebo>

<joint name="leg6_wheel6" type="continuous">
    	<parent link="leg6"/>
    	<child link="wheel6"/>
    	<origin xyz="-0.02 0 -0.315" rpy="0 1.5708 0"/>
        <limit effort="10.0" velocity="10.0"/>
        <axis xyz="0 0 1"/>
</joint>

<!-- front leg 1 -->

<link name="leg_front_1">

      <inertial>
	<origin xyz="0 0 0" rpy="0 0 0"/>
        <mass value="2.4"/>
        <inertia ixx="0.08036" iyy="0.07946" izz=" 0.00106" ixy="0" ixz="0" iyz="0"/>
      </inertial>

      <collision>
	<origin xyz="0 0 0" rpy="0 0 0"/>
        <geometry>
            <box size="0.02 0.07 0.63"/>
        </geometry>

      </collision>

      <visual>
	  <origin xyz="0 0 0" rpy="0 0 0"/>
          <geometry>
              <box size="0.02 0.07 0.63"/>
          </geometry>

          <material name="silver">
              <color rgba="1 0.5 0.75 1"/>
          </material>
      </visual>

</link>

<gazebo reference="leg_front_1">
        <material>Gazebo/Red</material>
	<kp>1000000.0</kp>
        <kd>1000000.0</kd>
        <mu1>0.1</mu1>
        <mu2>0.1</mu2>
</gazebo>

 <joint name="base_link_leg_front1_joint" type="fixed">
        <parent link="base_link"/>
        <child link="leg_front_1"/>
        <origin xyz="0.2 0.215 0" rpy="0 0 0"/>
</joint>
<link name="wheel_front1">
    
        <inertial>
	<origin xyz="0 0 0" rpy="0 0 0"/> 
            <mass value="0.21"/>
            <inertia ixx="6.2708e-5" iyy="6.2708e-5" izz="0.000125" ixy="0" ixz="0" iyz="0"/>
        </inertial>
        <collision>
	<origin xyz="0 0 0" rpy="0 0 0"/>
            <geometry>
                <cylinder length="0.024" radius="0.032"/>
            </geometry>
        </collision>

        <visual>
	<origin xyz="0 0 0" rpy="0 0 0"/>
            <geometry>
                <cylinder length="0.024" radius="0.032"/>
            </geometry>
            <material name="black">
                <color rgba="0 0 0 1"/>
            </material>
        </visual>
</link>

<gazebo reference="wheel_front1">
        <material>Gazebo/Green</material>
	<kp>1000000.0</kp>
        <kd>1000000.0</kd>
        <mu1>100.0</mu1>
        <mu2>100.0</mu2>
</gazebo>

<joint name="leg_front_1_wheel_front1" type="continuous">
    	<parent link="leg_front_1"/>
    	<child link="wheel_front1"/>
    	<origin xyz="0.022 0 -0.315" rpy="0 1.5708 0"/>
        <limit effort="10.0" velocity="10.0"/>
        <axis xyz="0 0 1"/>
</joint>



<!-- front leg 2 -->

<link name="leg_front_2">

      <inertial>
	<origin xyz="0 0 0" rpy="0 0 0"/>
        <mass value="2.4"/>
        <inertia ixx="0.08036" iyy="0.07946" izz=" 0.00106" ixy="0" ixz="0" iyz="0"/>
      </inertial>

      <collision>
	<origin xyz="0 0 0" rpy="0 0 0"/>
        <geometry>
            <box size="0.02 0.07 0.63"/>
        </geometry>

      </collision>

      <visual>
	  <origin xyz="0 0 0" rpy="0 0 0"/>
          <geometry>
              <box size="0.02 0.07 0.63"/>
          </geometry>

          <material name="silver">
              <color rgba="1 0.5 0.75 1"/>
          </material>
      </visual>

</link>

<gazebo reference="leg_front_2">
        <material>Gazebo/Red</material>
	<kp>1000000.0</kp>
        <kd>1000000.0</kd>
        <mu1>0.1</mu1>
        <mu2>0.1</mu2>
</gazebo>

 <joint name="base_link_leg_front2_joint" type="fixed">
        <parent link="base_link"/>
        <child link="leg_front_2"/>
        <origin xyz="-0.2 0.215 0" rpy="0 0 0"/>
</joint>
<link name="wheel_front2">
    
        <inertial>
	<origin xyz="0 0 0" rpy="0 0 0"/> 
            <mass value="0.21"/>
            <inertia ixx="6.2708e-5" iyy="6.2708e-5" izz="0.000125" ixy="0" ixz="0" iyz="0"/>
        </inertial>
        <collision>
	<origin xyz="0 0 0" rpy="0 0 0"/>
            <geometry>
                <cylinder length="0.024" radius="0.032"/>
            </geometry>
        </collision>

        <visual>
	<origin xyz="0 0 0" rpy="0 0 0"/>
            <geometry>
                <cylinder length="0.024" radius="0.032"/>
            </geometry>
            <material name="black">
                <color rgba="0 0 0 1"/>
            </material>
        </visual>
</link>

<gazebo reference="wheel_front2">
        <material>Gazebo/Green</material>
	<kp>1000000.0</kp>
        <kd>1000000.0</kd>
        <mu1>0.1</mu1>
        <mu2>0.1</mu2>
</gazebo>

<joint name="leg_front_2_wheel_front2" type="continuous">
    	<parent link="leg_front_2"/>
    	<child link="wheel_front2"/>
    	<origin xyz="-0.022 0 -0.315" rpy="0 1.5708 0"/>
        <limit effort="10.0" velocity="10.0"/>
        <axis xyz="0 0 1"/>
</joint>



<!-- back leg 1 -->

<link name="leg_back_1">

      <inertial>
	<origin xyz="0 0 0" rpy="0 0 0"/>
        <mass value="2.4"/>
        <inertia ixx="0.08036" iyy="0.07946" izz=" 0.00106" ixy="0" ixz="0" iyz="0"/>
      </inertial>

      <collision>
	<origin xyz="0 0 0" rpy="0 0 0"/>
        <geometry>
            <box size="0.02 0.07 0.63"/>
        </geometry>

      </collision>

      <visual>
	  <origin xyz="0 0 0" rpy="0 0 0"/>
          <geometry>
              <box size="0.02 0.07 0.63"/>
          </geometry>

          <material name="silver">
              <color rgba="1 0.5 0.75 1"/>
          </material>
      </visual>

</link>

<gazebo reference="leg_back_1">
        <material>Gazebo/Red</material>
	<kp>1000000.0</kp>
        <kd>1000000.0</kd>
        <mu1>0.1</mu1>
        <mu2>0.1</mu2>
</gazebo>

 <joint name="base_link_leg_back1_joint" type="fixed">
        <parent link="base_link"/>
        <child link="leg_back_1"/>
        <origin xyz="0.2 -0.215 0" rpy="0 0 0"/>
</joint>
<link name="wheel_back1">
    
        <inertial>
	<origin xyz="0 0 0" rpy="0 0 0"/> 
            <mass value="0.21"/>
            <inertia ixx="6.2708e-5" iyy="6.2708e-5" izz="0.000125" ixy="0" ixz="0" iyz="0"/>
        </inertial>
        <collision>
	<origin xyz="0 0 0" rpy="0 0 0"/>
            <geometry>
                <cylinder length="0.024" radius="0.032"/>
            </geometry>
        </collision>

        <visual>
	<origin xyz="0 0 0" rpy="0 0 0"/>
            <geometry>
                <cylinder length="0.024" radius="0.032"/>
            </geometry>
            <material name="black">
                <color rgba="0 0 0 1"/>
            </material>
        </visual>
</link>

<gazebo reference="wheel_back1">
        <material>Gazebo/Green</material>
	<kp>1000000.0</kp>
        <kd>1000000.0</kd>
</gazebo>

<joint name="leg_back_1_wheel_back1" type="continuous">
    	<parent link="leg_back_1"/>
    	<child link="wheel_back1"/>
    	<origin xyz="0.022 0 -0.315" rpy="0 1.5708 0"/>
        <limit effort="10.0" velocity="10.0"/>
        <axis xyz="0 0 1"/>
</joint>

<transmission name="left_wheel_transmission">
  <type>transmission_interface/SimpleTransmission</type>
  <joint name="leg_back_1_wheel_back1">
    <hardwareInterface>hardware_interface/VelocityJointInterface</hardwareInterface>  
  </joint>
  <actuator name="left_wheel_actuator">
    <mechanicalReduction>7</mechanicalReduction>
    <hardwareInterface>VelocityJointInterface</hardwareInterface>
  </actuator>
</transmission>

<!-- back leg 2 -->

<link name="leg_back_2">

      <inertial>
	<origin xyz="0 0 0" rpy="0 0 0"/>
        <mass value="2.4"/>
        <inertia ixx="0.08036" iyy="0.07946" izz=" 0.00106" ixy="0" ixz="0" iyz="0"/>
      </inertial>

      <collision>
	<origin xyz="0 0 0" rpy="0 0 0"/>
        <geometry>
            <box size="0.02 0.07 0.63"/>
        </geometry>

      </collision>

      <visual>
	  <origin xyz="0 0 0" rpy="0 0 0"/>
          <geometry>
              <box size="0.02 0.07 0.63"/>
          </geometry>

          <material name="silver">
              <color rgba="1 0.5 0.75 1"/>
          </material>
      </visual>

</link>

<gazebo reference="leg_back_2">
        <material>Gazebo/Red</material>
	<kp>1000000.0</kp>
        <kd>1000000.0</kd>
        <mu1>0.1</mu1>
        <mu2>0.1</mu2>
</gazebo>

 <joint name="base_link_leg_back2_joint" type="fixed">
        <parent link="base_link"/>
        <child link="leg_back_2"/>
        <origin xyz="-0.2 -0.215 0" rpy="0 0 0"/>
</joint>
<link name="wheel_back2">
    
        <inertial>
	<origin xyz="0 0 0" rpy="0 0 0"/> 
            <mass value="0.21"/>
            <inertia ixx="6.2708e-5" iyy="6.2708e-5" izz="0.000125" ixy="0" ixz="0" iyz="0"/>
        </inertial>
        <collision>
	<origin xyz="0 0 0" rpy="0 0 0"/>
            <geometry>
                <cylinder length="0.024" radius="0.032"/>
            </geometry>
        </collision>

        <visual>
	<origin xyz="0 0 0" rpy="0 0 0"/>
            <geometry>
                <cylinder length="0.024" radius="0.032"/>
            </geometry>
            <material name="black">
                <color rgba="0 0 0 1"/>
            </material>
        </visual>
</link>

<gazebo reference="wheel_back2">
        <material>Gazebo/Green</material>
	<kp>1000000.0</kp>
        <kd>1000000.0</kd>
</gazebo>



<joint name="leg_back_2_wheel_back2" type="continuous">
    	<parent link="leg_back_2"/>
    	<child link="wheel_back2"/>
    	<origin xyz="-0.022 0 -0.315" rpy="0 1.5708 0"/>
        <limit effort="10.0" velocity="10.0"/>
        <axis xyz="0 0 1"/>
</joint>

<transmission name="right_wheel_transmission">
  <type>transmission_interface/SimpleTransmission</type>
  <joint name="leg_back_2_wheel_back2">
    <hardwareInterface>hardware_interface/VelocityJointInterface</hardwareInterface>  
  </joint>
  <actuator name="right_wheel_actuator">
    <mechanicalReduction>7</mechanicalReduction>
    <hardwareInterface>VelocityJointInterface</hardwareInterface>
  </actuator>
</transmission>

<!-- camera link stair climber -->
    <link name="camera_link">
        <!-- Inertial for gazebo to take it into account, Put 1gr weight -->
        <inertial>
            <origin xyz="0 0 0" rpy="0 0 0"/>
            <mass value="0.001" />
            <inertia ixx="9.1875e-09" ixy="0.0" ixz="0.0" iyy="9.1875e-09" iyz="0.0" izz="1.378125e-08"/>
        </inertial>
		<visual>
            <origin rpy="0.0 0 0" xyz="0 0 0"/>
            <geometry>
                <box size="0.05 0.05 0.05"/>
            </geometry>
            <material name="green"/>
        </visual>
	</link>

    <gazebo reference="camera_link">
        <material>Gazebo/Orange</material>
    </gazebo>

    <joint name="head_camera_joint" type="fixed">
        <parent link="base_link"/>
        <child link="camera_link"/>
        <origin xyz="0 0.155 -0.04" rpy="0 0 0"/>
    </joint>


    <!-- camera -->
  <gazebo reference="camera_link">
    <sensor type="camera" name="camera1">
      <update_rate>10.0</update_rate>
      <camera name="head">

          <pose>0 0 0 0 0 1.57</pose>

        <horizontal_fov>1.3962634</horizontal_fov>
        <image>
          <width>400</width>
          <height>400</height>
          <format>R8G8B8</format>
        </image>
        <clip>
          <near>0.01</near>
          <far>100</far>
        </clip>
        <noise>
          <type>gaussian</type>
          <stddev>0.007</stddev>
        </noise>
      </camera>
      <plugin name="camera_controller" filename="libgazebo_ros_camera.so">
        <alwaysOn>true</alwaysOn>
        <updateRate>0.0</updateRate>
        <cameraName>jibo/camera1</cameraName>
        <imageTopicName>image_raw</imageTopicName>
        <cameraInfoTopicName>camera_info</cameraInfoTopicName>
        <frameName>camera_link</frameName>
        <hackBaseline>0.07</hackBaseline>
        <distortionK1>0.0</distortionK1>
        <distortionK2>0.0</distortionK2>
        <distortionK3>0.0</distortionK3>
        <distortionT1>0.0</distortionT1>
        <distortionT2>0.0</distortionT2>
      </plugin>
    </sensor>
  </gazebo>

<!-- sonar plugin -->

<link name="base_sonar_front">
    <collision>
      <origin xyz="0 0 0" rpy="0 0 0"/>
      <geometry>
        <box size="0.01 0.01 0.01"/>
      </geometry>
    </collision>
    <visual>
      <origin xyz="0 0 0" rpy="0 0 0"/>
      <geometry>
        <box size="0.01 0.01 0.01"/>
      </geometry>
    </visual>
    <inertial>
      <mass value="1e-5" />
      <origin xyz="0 0 0" rpy="0 0 0"/>
      <inertia ixx="1e-6" ixy="0" ixz="0" iyy="1e-6" iyz="0" izz="1e-6" />
    </inertial>
 </link>
 <joint name="sonar_front_joint" type="fixed">
    <axis xyz="0 1 0" />
    <origin rpy="0 0 1.517" xyz="-0.015 0.04 -0.3" />
    <parent link="leg1"/>
    <child link="base_sonar_front"/>
</joint>
<gazebo reference="base_sonar_front">
        <material>Gazebo/Orange</material>
</gazebo>
   <gazebo reference="base_sonar_front">        
   <sensor type="ray" name="TeraRanger">
      <pose>0 0 0 0 0 0</pose>
      <visualize>true</visualize>
      <update_rate>50</update_rate>
      <ray>
         <scan>
            <horizontal>
               <samples>10</samples>
               <resolution>1</resolution> 
               <min_angle>-0.04</min_angle>
               <max_angle>0.04</max_angle>
            </horizontal>
            <vertical>
               <samples>10</samples>
               <resolution>1</resolution> 
               <min_angle>-0.04</min_angle>
               <max_angle>0.04</max_angle> 
            </vertical>
         </scan>
         <range>
            <min>0.01</min>
            <max>20</max>
            <resolution>0.02</resolution>
         </range>
      </ray>
      <plugin filename="libgazebo_ros_range.so" name="gazebo_ros_range">
         <gaussianNoise>0.005</gaussianNoise>
         <alwaysOn>true</alwaysOn>
         <updateRate>50</updateRate>
         <topicName>sensor/sonar_front</topicName>
         <frameName>base_sonar_front</frameName>
         <radiation>INFRARED</radiation>
         <fov>0.2967</fov>
      </plugin>
   </sensor>  
   </gazebo>

   <!-- sonar plugin 2 -->

<link name="base_sonar_front_2">
    <collision>
      <origin xyz="0 0 0" rpy="0 0 0"/>
      <geometry>
        <box size="0.01 0.01 0.01"/>
      </geometry>
    </collision>
    <visual>
      <origin xyz="0 0 0" rpy="0 0 0"/>
      <geometry>
        <box size="0.01 0.01 0.01"/>
      </geometry>
    </visual>
    <inertial>
      <mass value="1e-5" />
      <origin xyz="0 0 0" rpy="0 0 0"/>
      <inertia ixx="1e-6" ixy="0" ixz="0" iyy="1e-6" iyz="0" izz="1e-6" />
    </inertial>
 </link>
 <joint name="sonar_front_joint_2" type="fixed">
    <axis xyz="0 1 0" />
    <origin rpy="0 0 1.517" xyz="0.015 0.04 -0.3" />
    <parent link="leg2"/>
    <child link="base_sonar_front_2"/>
</joint>
<gazebo reference="base_sonar_front_2">
        <material>Gazebo/Orange</material>
</gazebo>
   <gazebo reference="base_sonar_front_2">        
   <sensor type="ray" name="TeraRanger">
      <pose>0 0 0 0 0 0</pose>
      <visualize>true</visualize>
      <update_rate>50</update_rate>
      <ray>
         <scan>
            <horizontal>
               <samples>10</samples>
               <resolution>1</resolution> 
               <min_angle>-0.04</min_angle>
               <max_angle>0.04</max_angle>
            </horizontal>
            <vertical>
               <samples>10</samples>
               <resolution>1</resolution> 
               <min_angle>-0.04</min_angle>
               <max_angle>0.04</max_angle> 
            </vertical>
         </scan>
         <range>
            <min>0.01</min>
            <max>20</max>
            <resolution>0.02</resolution>
         </range>
      </ray>
      <plugin filename="libgazebo_ros_range.so" name="gazebo_ros_range">
         <gaussianNoise>0.005</gaussianNoise>
         <alwaysOn>true</alwaysOn>
         <updateRate>50</updateRate>
         <topicName>sensor/sonar_front_2</topicName>
         <frameName>base_sonar_front_2</frameName>
         <radiation>INFRARED</radiation>
         <fov>0.2967</fov>
      </plugin>
   </sensor>  
   </gazebo>
</robot>

